<?xml version="1.0" encoding="utf-8"?>
<!-- =================================================================================== -->
<!-- |    This document was autogenerated by xacro from m2wr.xacro                     | -->
<!-- |    EDITING THIS FILE BY HAND IS NOT RECOMMENDED                                 | -->
<!-- =================================================================================== -->
<robot name="m2wr">
  <material name="black">
    <color rgba="0.0 0.0 0.0 1"/>
  </material>
  <material name="blue">
    <color rgba="0 0 1.0 1"/>
  </material>
  <material name="green">
    <color rgba="0 0.8 0.0 1"/>
  </material>
  <material name="gray">
    <color rgba="0.2 0.2 0.2 1"/>
  </material>
  <material name="orange">
    <color rgba="1.0 0.4235294 0.0392156 1"/>
  </material>
  <material name="brown">
    <color rgba="0.87058823 0.8117647 0.764705882 1"/>
  </material>
  <material name="red">
    <color rgba="0.80078125 0.12890625 0.1328125 1"/>
  </material>
  <material name="white">
    <color rgba="1.0 1.0 1.0 1"/>
  </material>
  <gazebo reference="link_chassis">
    <meterial>Gazebo/Orange</meterial>
  </gazebo>
  <gazebo reference="link_left_wheel">
    <meterial>Gazebo/Red</meterial>
  </gazebo>
  <gazebo reference="link_right_wheel">
    <meterial>Gazebo/Red</meterial>
  </gazebo>
  <!--Gazebo Control Plugin -->
  <gazebo>
    <plugin filename="libgazebo_ros_control.so" name="gazebo_ros_control">
      <robotNamespace>/ddr_control</robotNamespace>
    </plugin>
  </gazebo>
  <!-- hokuyo Laser Sensor -->
  <gazebo reference="sensor_laser">
    <sensor name="head_hokuyo_sensor" type="ray">
      <pose>0 0 0 0 0 0</pose>
      <visualize>false</visualize>
      <update_rate>20</update_rate>
      <ray>
        <scan>
          <horizontal>
            <samples>720</samples>
            <resolution>1</resolution>
            <min_angle>-1.570796</min_angle>
            <max_angle>1.570796</max_angle>
          </horizontal>
        </scan>
        <range>
          <min>0.10</min>
          <max>30.0</max>
          <resolution>0.01</resolution>
        </range>
        <noise>
          <type>gaussian</type>
          <mean>0.0</mean>
          <stddev>0.01</stddev>
        </noise>
      </ray>
      <plugin filename="libgazebo_ros_laser.so" name="gazebo_ros_head_hokuyo_controller">
        <topicName>/ddr_robot/laser/scan</topicName>
        <frameName>sensor_laser</frameName>
      </plugin>
    </sensor>
  </gazebo>
  <!-- camera -->
  <gazebo reference="link_camera">
    <sensor name="camera1" type="camera">
      <update_rate>30.0</update_rate>
      <camera name="head">
        <horizontal_fov>1.3962634</horizontal_fov>
        <image>
          <width>800</width>
          <height>800</height>
          <format>R8G8B8</format>
        </image>
        <clip>
          <near>0.02</near>
          <far>300</far>
        </clip>
        <noise>
          <type>gaussian</type>
          <!-- Noise is sampled independently per pixel on each frame.
                        That pixel's noise value is added to each of its color
                        channels, which at that point lie in the range [0,1]. -->
          <mean>0.0</mean>
          <stddev>0.007</stddev>
        </noise>
      </camera>
      <plugin filename="libgazebo_ros_camera.so" name="camera_controller">
        <alwaysOn>true</alwaysOn>
        <updateRate>0.0</updateRate>
        <cameraName>rrbot/camera1</cameraName>
        <imageTopicName>image_raw</imageTopicName>
        <cameraInfoTopicName>camera_info</cameraInfoTopicName>
        <frameName>camera_link</frameName>
        <hackBaseline>0.07</hackBaseline>
        <distortionK1>0.0</distortionK1>
        <distortionK2>0.0</distortionK2>
        <distortionK3>0.0</distortionK3>
        <distortionT1>0.0</distortionT1>
        <distortionT2>0.0</distortionT2>
      </plugin>
    </sensor>
  </gazebo>
  <!-- robot_chassis -->
  <link name="link_chassis">
    <pose>0 0 0 0 0 0</pose>
    <inertial>
      <mass value="5"/>
      <origin rpy="0 0 0" xyz="0 0 0"/>
      <inertia ixx="0.0395416666667" ixy="0" ixz="0" iyy="0.1062083333" iyz="0" izz="0.1062083333"/>
    </inertial>
    <collision name="collision_chassis">
      <geometry>
        <box size="0.5 0.3 0.07"/>
      </geometry>
    </collision>
    <visual>
      <origin rpy="0 0 0" xyz="0 0 0"/>
      <geometry>
        <box size="0.5 0.3 0.07"/>
      </geometry>
      <material name="">
        <color rgba="0 1 0.1 1"/>
      </material>
    </visual>
  </link>
  <!-- caster_wheel -->
  <link name="custer_wheel">
    <inertial>
      <mass value="1"/>
      <origin rpy="0 0 0" xyz="0 0 0"/>
      <inertia ixx="0.0003721" ixy="0" ixz="0" iyy="0.0003721" iyz="0" izz="0.0003721"/>
    </inertial>
    <collision name="caster_front_collision">
      <origin rpy="0 0 0" xyz="0 0 0"/>
      <geometry>
        <sphere radius="0.0305"/>
      </geometry>
    </collision>
    <visual name="caster_front_visual">
      <origin rpy="0 0 0" xyz="0 0 0"/>
      <geometry>
        <sphere radius="0.0325"/>
      </geometry>
    </visual>
  </link>
  <!-- caster_wheel_joint -->
  <joint name="joint_custer" type="continuous">
    <origin rpy="0 0 0" xyz="0.2 0 -0.0675"/>
    <child link="custer_wheel"/>
    <parent link="link_chassis"/>
    <axis rpy="0 0 0" xyz="1 1 1"/>
    <limit effort="10000" velocity="1000"/>
    <joint_properties damping="0" friction="0"/>
  </joint>
  <!-- Laser_Sensor -->
  <link name="sensor_laser">
    <inertial>
      <mass value="1"/>
      <origin rpy="0 0 0" xyz="0 0 0"/>
      <inertia ixx="0.00145833333333" ixy="0" ixz="0" iyy="0.00145833333333" iyz="0" izz="0.00125"/>
    </inertial>
    <collision name="collision_chassis">
      <geometry>
        <cylinder length="0.1" radius="0.05"/>
      </geometry>
    </collision>
    <visual>
      <origin rpy="0 0 0" xyz="0 0 0"/>
      <geometry>
        <cylinder length="0.1" radius="0.05"/>
      </geometry>
      <material name="">
        <color rgba="0 0.1 1 1"/>
      </material>
    </visual>
  </link>
  <!-- Laser_Sensor_joint -->
  <joint name="joint_sensor_laser" type="fixed">
    <origin rpy="0.0 0.0 0.0" xyz="0.15 0.0 0.05"/>
    <parent link="link_chassis"/>
    <child link="sensor_laser"/>
  </joint>
  <link name="link_right_wheel">
    <inertial>
      <mass value="0.2"/>
      <origin rpy="0 1.5707 1.5707" xyz="0 0 0"/>
      <inertia ixx="0.00052667" ixy="0" ixz="0" iyy="0.0005266" iyz="0" izz="0.001"/>
    </inertial>
    <collision name="link_right_wheel_collision">
      <origin rpy="0 1.5707 1.5707" xyz="0 0 0"/>
      <geometry>
        <cylinder length="0.04" radius="0.1"/>
      </geometry>
    </collision>
    <visual name="link_right_wheel_visual">
      <origin rpy="0 1.5707 1.5707" xyz="0 0 0"/>
      <geometry>
        <cylinder length="0.04" radius="0.1"/>
      </geometry>
      <meterial name="blue"/>
    </visual>
  </link>
  <link name="link_left_wheel">
    <inertial>
      <mass value="0.2"/>
      <origin rpy="0 1.5707 1.5707" xyz="0 0 0"/>
      <inertia ixx="0.00052667" ixy="0" ixz="0" iyy="0.0005266" iyz="0" izz="0.001"/>
    </inertial>
    <collision name="link_left_wheel_collision">
      <origin rpy="0 1.5707 1.5707" xyz="0 0 0"/>
      <geometry>
        <cylinder length="0.04" radius="0.1"/>
      </geometry>
    </collision>
    <visual name="link_left_wheel_visual">
      <origin rpy="0 1.5707 1.5707" xyz="0 0 0"/>
      <geometry>
        <cylinder length="0.04" radius="0.1"/>
      </geometry>
      <meterial name="blue"/>
    </visual>
  </link>
  <joint name="joint_right_wheel" type="continuous">
    <origin rpy="0 0 0" xyz="-0.05 0.18 0"/>
    <child link="link_right_wheel"/>
    <parent link="link_chassis"/>
    <axis rpy="0 0 0" xyz="0 1 0"/>
    <limit effort="10000" velocity="1000"/>
    <joint_properties damping="0.01" friction="0.001"/>
  </joint>
  <joint name="joint_left_wheel" type="continuous">
    <origin rpy="0 0 0" xyz="-0.05 -0.18 0"/>
    <child link="link_left_wheel"/>
    <parent link="link_chassis"/>
    <axis rpy="0 0 0" xyz="0 1 0"/>
    <limit effort="10000" velocity="1000"/>
    <joint_properties damping="0.01" friction="0.001"/>
  </joint>
  <transmission name="right">
    <type>transmission_interface/SimpleTransmission</type>
    <joint name="joint_right_wheel">
      <hardwareInterface>EffortJointInterface</hardwareInterface>
    </joint>
    <actuator name="right_motor">
      <hardwareInterface>EffortJointInterface</hardwareInterface>
      <mechanicalReduction>1</mechanicalReduction>
    </actuator>
  </transmission>
  <transmission name="left">
    <type>transmission_interface/SimpleTransmission</type>
    <joint name="joint_left_wheel">
      <hardwareInterface>EffortJointInterface</hardwareInterface>
    </joint>
    <actuator name="left_motor">
      <hardwareInterface>EffortJointInterface</hardwareInterface>
      <mechanicalReduction>1</mechanicalReduction>
    </actuator>
  </transmission>
  <!--Camera box -->
  <link name="link_camera">
    <pose>0 0 0 0 0 0</pose>
    <inertial>
      <mass value="0.1"/>
      <origin rpy="0 0 0" xyz="0 0 0"/>
      <inertia ixx="0.00008166" ixy="0" ixz="0" iyy="0.00008166" iyz="0" izz="0.00008166"/>
    </inertial>
    <collision name="collision_camera">
      <geometry>
        <box size="0.035 0.07 0.07"/>
      </geometry>
    </collision>
    <visual>
      <origin rpy="0 0 0" xyz="0 0 0"/>
      <geometry>
        <box size="0.035 0.07 0.07"/>
      </geometry>
      <material name="">
        <color rgba="1 1 1 1"/>
      </material>
    </visual>
  </link>
  <!-- camera_joint -->
  <joint name="joint_camera" type="fixed">
    <origin rpy="0 0 0" xyz="0.2675 0 0"/>
    <child link="link_camera"/>
    <parent link="link_chassis"/>
  </joint>
</robot>
